Workbook

Sheet Ports
A1: USB-C SuperSpeed hub — 4 ports only (1 in + 3 out)
A2: Connectors on the board: four Type-C receptacles. No barrel jack, no USB-A, no extra PD inlet. Hardware-only (no MCU). Power comes from the input Type-C VBUS (host 5 V).
A4: Ref | B4: Port | C4: Connector | D4: Role | E4: Power
A5: J1 | B5: UP0 INPUT | C5: Type-C 24-pin mid-mount 5 A | D5: UFP to host + SuperSpeed uplink | E5: Sink 5 V from host. HD3SS3220 PORT=GND (UFP). No 20 V. Does not charge the host.
A6: J2 | B6: DS1 OUTPUT | C6: Type-C 24-pin mid-mount 5 A | D6: DFP to device + SuperSpeed | E6: Source 5 V, ILIM 1.0 A (TPS2553). HD3SS3220 PORT=VDD (DFP), CURRENT_MODE=3 A advert.
A7: J3 | B7: DS2 OUTPUT | C7: Type-C 24-pin mid-mount 5 A | D7: DFP to device + SuperSpeed | E7: Same as DS1.
A8: J4 | B8: DS3 OUTPUT | C8: Type-C 24-pin mid-mount 5 A | D8: DFP to device + SuperSpeed | E8: Same as DS1.
A10: POWER FACT (not optional): with only these four Type-C parts there is no second inlet. Total energy is whatever the host puts on UP0 VBUS — typically 5 V × 1.5 A = 7.5 W or 5 V × 3 A = 15 W. Hub silicon needs ~4 W. That leaves ~3–11 W for all three outputs combined. BOM sets each DS switch to 1.0 A so one fat SSD cannot collapse the host port; three outputs at 1 A is still more than the host can give, so the host’s own current limit will fold first. This is the cost of “four connectors, no brick.” 100 W / 20 V per port is not on this list.
A14: ICs on this board (big brand, hardware strap, no firmware image)
A15: Qty | B15: MPN | C15: Mfr | D15: Function | E15: Strap
A16: 1 | B16: TUSB8041ARGCR | C16: Texas Instruments | D16: 4-port USB 3.1 Gen1 hub | E16: SDA/SCL floating — default descriptors
A17: 1 | B17: HD3SS3220RNHR | C17: Texas Instruments | D17: UP0 CC + SS mux | E17: PORT=GND UFP
A18: 3 | B18: HD3SS3220RNHR | C18: Texas Instruments | D18: DS1–DS3 CC + SS mux | E18: PORT=5V DFP, CURRENT_MODE=3A
A19: 3 | B19: TPS2553DBVR | C19: Texas Instruments | D19: DS VBUS 1.0 A limit | E19: RILIM ≈ 24.9 kΩ, EN from mux ID
A20: 1 | B20: TLV75533PDRVR | C20: Texas Instruments | D20: 5 V → 3.3 V | E20: from SYS_5V
A21: 1 | B21: TPS74801DRCR | C21: Texas Instruments | D21: 5 V → 1.1 V hub core | E21: sequence after 3.3 V

Sheet BOM
A1: BOM — 1 × Type-C input + 3 × Type-C output
A2: Yellow = qty and unit price (USD qty-1 ballpark). Ext = Qty × Unit. No barrel jack line. No MCU. No 5th connector.
A4: Item | B4: Qty | C4: Ref des | D4: MPN | E4: Mfr | F4: Description | G4: Package | H4: Cat | I4: Unit USD | J4: Ext USD | K4: Note
A5: 1 | B5: 1 | C5: U1 | D5: TUSB8041ARGCR | E5: Texas Instruments | F5: 4-port USB 3.1 Gen1 SuperSpeed hub | G5: VQFN-64 9×9 | H5: DATA | I5: 5.4 | J5: =B5*I5 -> 5.4 | K5: SDA/SCL no pull-up. SMBUSz NC. GRSTz = 1 µF to GND.
A6: 2 | B6: 1 | C6: Y1 | D6: ABM8-24.000MHZ-B2-T | E6: Abracon | F6: 24.000 MHz ±20 ppm crystal | G6: 3.2×2.5 | H6: DATA | I6: 0.55 | J6: =B6*I6 -> 0.55 | K6: Load caps per Abracon CL. Not 25 MHz.
A7: 3 | B7: 2 | C7: C_y | D7: GRM1555C1H120JA01D | E7: Murata | F7: 12 pF C0G 0402 crystal load (adjust to CL) | G7: 0402 | H7: PASS | I7: 0.03 | J7: =B7*I7 -> 0.06 | K7: Tune if oscillator amplitude is low.
A8: 4 | B8: 1 | C8: U2 | D8: HD3SS3220RNHR | E8: Texas Instruments | F8: UP0 Type-C CC controller + 10 Gbps 2:1 SS mux | G8: WQFN-30 | H8: CC | I8: 1.85 | J8: =B8*I8 -> 1.85 | K8: PORT pin to GND = UFP. VBUS_DET 900 kΩ to J1 VBUS.
A9: 5 | B9: 1 | C9: U3 | D9: HD3SS3220RNHR | E9: Texas Instruments | F9: DS1 Type-C CC + SS mux | G9: WQFN-30 | H9: CC | I9: 1.85 | J9: =B9*I9 -> 1.85 | K9: PORT to 5 V = DFP. CURRENT_MODE to 5 V = 3 A advert. ID → U6 EN.
A10: 6 | B10: 1 | C10: U4 | D10: HD3SS3220RNHR | E10: Texas Instruments | F10: DS2 Type-C CC + SS mux | G10: WQFN-30 | H10: CC | I10: 1.85 | J10: =B10*I10 -> 1.85 | K10: Same strap as U3. ID → U7 EN.
A11: 7 | B11: 1 | C11: U5 | D11: HD3SS3220RNHR | E11: Texas Instruments | F11: DS3 Type-C CC + SS mux | G11: WQFN-30 | H11: CC | I11: 1.85 | J11: =B11*I11 -> 1.85 | K11: Same strap as U3. ID → U8 EN.
A12: 8 | B12: 1 | C12: U6 | D12: TPS2553DBVR | E12: Texas Instruments | F12: DS1 VBUS switch, 1.0 A typ | G12: SOT-23-6 | H12: POWER | I12: 0.85 | J12: =B12*I12 -> 0.85 | K12: RILIM 24.9 kΩ 1%. FAULT# → hub OVERCUR1z.
A13: 9 | B13: 1 | C13: U7 | D13: TPS2553DBVR | E13: Texas Instruments | F13: DS2 VBUS switch, 1.0 A typ | G13: SOT-23-6 | H13: POWER | I13: 0.85 | J13: =B13*I13 -> 0.85 | K13: FAULT# → OVERCUR2z.
A14: 10 | B14: 1 | C14: U8 | D14: TPS2553DBVR | E14: Texas Instruments | F14: DS3 VBUS switch, 1.0 A typ | G14: SOT-23-6 | H14: POWER | I14: 0.85 | J14: =B14*I14 -> 0.85 | K14: FAULT# → OVERCUR3z.
A15: 11 | B15: 3 | C15: Rilim | D15: RC0402FR-0724K9L | E15: Yageo | F15: 24.9 kΩ 1% 0402 TPS2553 ILIM | G15: 0402 | H15: PASS | I15: 0.03 | J15: =B15*I15 -> 0.09 | K15: ≈ 1.0 A. Do not leave ILIM open (that is ~75 mA).
A16: 12 | B16: 1 | C16: U31 | D16: TLV75533PDRVR | E16: Texas Instruments | F16: SYS_5V → 3.3 V 500 mA LDO | G16: WSON-6 | H16: POWER | I16: 0.45 | J16: =B16*I16 -> 0.45 | K16: Hub VDD33, mux VDD, CC rails.
... A20: 16 | B20: 1 | C20: J2 | D20: 124019572112A | E20: Amphenol ICC | F20: OUTPUT DS1 Type-C receptacle 24-pin mid-mount 5 A | G20: Mid-mount hybrid | H20: CONN | I20: 2.27 | J20: =B20*I20 -> 2.27 | K20: Same footprint as J1.
A21: 17 | B21: 1 | C21: J3 | D21: 124019572112A | E21: Amphenol ICC | F21: OUTPUT DS2 Type-C receptacle 24-pin mid-mount 5 A | G21: Mid-mount hybrid | H21: CONN | I21: 2.27 | J21: =B21*I21 -> 2.27
A22: 18 | B22: 1 | C22: J4 | D22: 124019572112A | E22: Amphenol ICC | F22: OUTPUT DS3 Type-C receptacle 24-pin mid-mount 5 A | G22: Mid-mount hybrid | H22: CONN | I22: 2.27 | J22: =B22*I22 -> 2.27
A23: 19 | B23: 8 | C23: Uesd_ss | D23: TPD2EUSB30DRTR | E23: Texas Instruments | F23: 2-ch SuperSpeed ESD, low-C (2 per Type-C: lane1 + lane2) | G23: SOT-5 | H23: PROT | I23: 0.42 | J23: =B23*I23 -> 3.36 | K23: Place <1 mm from connector pads.
A24: 20 | B24: 4 | C24: Uesd_cc | D24: TPD4E05U06DQAR | E24: Texas Instruments | F24: 4-ch ESD for D+/D−/CC1/CC2, one per Type-C | G24: USON-10 | H24: PROT | I24: 0.38 | J24: =B24*I24 -> 1.52
A25: 21 | B25: 4 | C25: Dtv | D25: PESD5V0S1UL | E25: Nexperia | F25: 5 V TVS on each VBUS (host is 5 V only) | G25: SOD-323 | H25: PROT | I25: 0.08 | J25: =B25*I25 -> 0.32 | K25: Do not put TVS2200 here — this board never sees 20 V.
A26: 22 | B26: 16 | C26: Cac | D26: GCM155R71C104KA55D | E26: Murata | F26: 100 nF 16 V 0402 SS TX AC-coupling | G26: 0402 | H26: PASS | I26: 0.04 | J26: =B26*I26 -> 0.64 | K26: 4 per port. Follow HD3SS3220 datasheet side-of-mux.
A27: 23 | B27: 4 | C27: R900k | D27: RC0402FR-07900KL | E27: Yageo | F27: 900 kΩ VBUS_DET on each HD3SS3220 | G27: 0402 | H27: PASS | I27: 0.02 | J27: =B27*I27 -> 0.08 | K27: Datasheet value. Do not 10 k.
A28: 24 | B28: 3 | C28: R200k | D28: RC0402FR-07200KL | E28: Yageo | F28: 200 kΩ pull-up on DS ID pins | G28: 0402 | H28: PASS | I28: 0.02 | J28: =B28*I28 -> 0.06 | K28: ID is open-drain.
A29: 25 | B29: 4 | C29: Cblk5 | D29: GRM21BR61A226ME51L | E29: Murata | F29: 22 µF 10 V 0805 on each Type-C VBUS | G29: 0805 | H29: PASS | I29: 0.08 | J29: =B29*I29 -> 0.32 | K29: Plus 180 µF polymer on hub 5 V (next line).
A30: 26 | B30: 1 | C30: Cbulk | D30: 16SVP180MX | E30: Panasonic | F30: 180 µF 16 V OS-CON on SYS_5V (USB hub bulk) | G30: 8 mm | H30: PASS | I30: 0.85 | J30: =B30*I30 -> 0.85 | K30: USB spec ≥120 µF on hub downstream 5 V domain.
A31: 27 | B31: 20 | C31: C10u | D31: GRM155R70J106ME15D | E31: Murata | F31: 10 µF 6.3 V 0402 local decouple | G31: 0402 | H31: PASS | I31: 0.03 | J31: =B31*I31 -> 0.6 | K31: Under every QFN.
A32: 28 | B32: 24 | C32: C100n | D32: GRM155R71C104KA88D | E32: Murata | F32: 100 nF 16 V 0402 per power pin | G32: 0402 | H32: PASS | I32: 0.02 | J32: =B32*I32 -> 0.48
A33: 29 | B33: 2 | C33: Rfb | D33: RC0402FR-074K99L | E33: Yageo | F33: TPS74801 FB divider (set 1.1 V — confirm ratio in datasheet) | G33: 0402 | H33: PASS | I33: 0.02 | J33: =B33*I33 -> 0.04 | K33: Replace with exact divider from TPS74801 1.1 V example.
A34: 30 | B34: 1 | C34: Cgrst | D34: GRM155R71C105KA12D | E34: Murata | F34: 1 µF on TUSB8041A GRSTz to GND | G34: 0402 | H34: PASS | I34: 0.04 | J34: =B34*I34 -> 0.04 | K34: Reset delay.
A35: 31 | B35: 1 | C35: PCB | D35: JLC04161H-7628 ENIG + stencil | E35: JLCPCB | F35: 4-layer 1.6 mm, 90 Ω diff coupon, ENIG, ~80×50 mm | G35: 4-layer | H35: MECH | I35: 18 | J35: =B35*I35 -> 18 | K35: Sig-GND-PWR-Sig. Stencil 0.12 mm for 0.4 mm QFN.
A36: 32 | B36: 4 | C36: MH | D36: R30-1000402 | E36: Harwin | F36: M3 standoff + screw | G36: M3 | H36: MECH | I36: 0.4 | J36: =B36*I36 -> 1.6
H37: TOTAL | J37: =SUM(J5:J36) -> 55.14
A39: By category
A40: Category | B40: Ext USD | C40: Share
A41: DATA | B41: =SUMIF($H$5:$H$36,A41,$J$5:$J$36) -> 5.95 | C41: =IF($J$37=0,0,B41/$J$37) -> 0.10790715
A42: CC | B42: =SUMIF($H$5:$H$36,A42,$J$5:$J$36) -> 7.4 | C42: =IF($J$37=0,0,B42/$J$37) -> 0.13420384
A43: POWER | B43: =SUMIF($H$5:$H$36,A43,$J$5:$J$36) -> 4.65 | C43: =IF($J$37=0,0,B43/$J$37) -> 0.084330794
A44: PROT | B44: =SUMIF($H$5:$H$36,A44,$J$5:$J$36) -> 5.2 | C44: =IF($J$37=0,0,B44/$J$37) -> 0.094305404
A45: CONN | B45: =SUMIF($H$5:$H$36,A45,$J$5:$J$36) -> 9.08 | C45: =IF($J$37=0,0,B45/$J$37) -> 0.16467174
...

Sheet Counts
A1: Connector and IC count check (must equal 4 Type-C)
A3: What | B3: Must be | C3: On this BOM | D3: Pass?
A4: Type-C receptacles (124019572112A) | B4: 4 | C4: =SUMIF(BOM!D:D,"124019572112A",BOM!B:B) -> 4 | D4: =IF(C4=B4,"PASS","FAIL") -> PASS
A5: HD3SS3220 (one per Type-C) | B5: 4 | C5: =SUMIF(BOM!D:D,"HD3SS3220RNHR",BOM!B:B) -> 4 | D5: =IF(C5=B5,"PASS","FAIL") -> PASS
A6: TPS2553 (outputs only) | B6: 3 | C6: =SUMIF(BOM!D:D,"TPS2553DBVR",BOM!B:B) -> 3 | D6: =IF(C6=B6,"PASS","FAIL") -> PASS
A7: TUSB8041A hub | B7: 1 | C7: =SUMIF(BOM!D:D,"TUSB8041ARGCR",BOM!B:B) -> 1 | D7: =IF(C7=B7,"PASS","FAIL") -> PASS
A8: Barrel / DC jack lines | B8: 0 | C8: =COUNTIF(BOM!F:F,"*Barrel*") -> 0 | D8: =IF(C8=B8,"PASS","FAIL") -> PASS
A9: MCU lines (STM32/MSP) | B9: 0 | C9: =COUNTIF(BOM!D:D,"*STM32*")+COUNTIF(BOM!D:D,"*MSP*") -> 0 | D9: =IF(C9=B9,"PASS","FAIL") -> PASS
