Workbook

Sheet BOM
A1: Case C complete BOM — 1 Type-C in + 3 Type-C out | SOT-23 LDO 3.3 V + SOT-23 buck 1.1 V
A2: No MCU. No barrel. Host 5 V only. Hand-solder converters: TLV75533PDBVR (5→3.3 SOT-23-5) + TLV62569PDDCR (5→1.1 SOT-23-6). Size 1.1 V for 0.70 A (563 mA typ 3×SS U0). USD qty-1 cut-tape ballpark. Yellow = inputs. Ext = Qty×Unit.
A4: Item | B4: Qty | C4: Ref des | D4: MPN | E4: Mfr | F4: Description | G4: Package | H4: Cat | I4: Unit USD | J4: Ext USD | K4: DNP | L4: Note
A5: 1 | B5: 1 | C5: U1 | D5: TUSB8041ARGCR | E5: Texas Instruments | F5: 4-port USB 3.1 Gen1 SuperSpeed hub | G5: VQFN-64 | H5: DATA | I5: 5.4 | J5: =B5*I5 -> 5.4 | L5: SDA/SCL floating. SMBUSz NC. GRSTz = 1 µF to GND, released after 3.3 V and 1.1 V up.
A6: 2 | B6: 1 | C6: Y1 | D6: ABM8-24.000MHZ-B2-T | E6: Abracon | F6: 24.000 MHz crystal ±20 ppm | G6: 3.2×2.5 | H6: DATA | I6: 0.55 | J6: =B6*I6 -> 0.55 | L6: Next to XI/XO. Away from L32.
A7: 3 | B7: 2 | C7: C_y | D7: GRM1555C1H120JA01D | E7: Murata | F7: 12 pF C0G crystal load | G7: 0402 | H7: PASS | I7: 0.03 | J7: =B7*I7 -> 0.06 | L7: Tune to crystal CL.
A8: 4 | B8: 1 | C8: U2 | D8: HD3SS3220RNHR | E8: Texas Instruments | F8: UP0 CC + 10 Gbps 2:1 SS mux, PORT=UFP | G8: WQFN-30 | H8: CC | I8: 1.85 | J8: =B8*I8 -> 1.85 | L8: PORT to GND. VBUS_DET 900 kΩ to J1 VBUS.
A9: 5 | B9: 1 | C9: U3 | D9: HD3SS3220RNHR | E9: Texas Instruments | F9: DS1 CC + SS mux, PORT=DFP | G9: WQFN-30 | H9: CC | I9: 1.85 | J9: =B9*I9 -> 1.85 | L9: PORT to 5 V. CURRENT_MODE to 5 V = 3 A advert. ID → U6 EN.
A10: 6 | B10: 1 | C10: U4 | D10: HD3SS3220RNHR | E10: Texas Instruments | F10: DS2 CC + SS mux, PORT=DFP | G10: WQFN-30 | H10: CC | I10: 1.85 | J10: =B10*I10 -> 1.85 | L10: ID → U7 EN.
A11: 7 | B11: 1 | C11: U5 | D11: HD3SS3220RNHR | E11: Texas Instruments | F11: DS3 CC + SS mux, PORT=DFP | G11: WQFN-30 | H11: CC | I11: 1.85 | J11: =B11*I11 -> 1.85 | L11: ID → U8 EN.
A12: 8 | B12: 1 | C12: U6 | D12: TPS2553DBVR | E12: Texas Instruments | F12: DS1 VBUS switch ~1.0 A | G12: SOT-23-6 | H12: POWER | I12: 0.85 | J12: =B12*I12 -> 0.85 | L12: FAULT# → OVERCUR1z.
A13: 9 | B13: 1 | C13: U7 | D13: TPS2553DBVR | E13: Texas Instruments | F13: DS2 VBUS switch ~1.0 A | G13: SOT-23-6 | H13: POWER | I13: 0.85 | J13: =B13*I13 -> 0.85 | L13: FAULT# → OVERCUR2z.
A14: 10 | B14: 1 | C14: U8 | D14: TPS2553DBVR | E14: Texas Instruments | F14: DS3 VBUS switch ~1.0 A | G14: SOT-23-6 | H14: POWER | I14: 0.85 | J14: =B14*I14 -> 0.85 | L14: FAULT# → OVERCUR3z.
A15: 11 | B15: 3 | C15: Rilim | D15: RC0402FR-0724K9L | E15: Yageo | F15: 24.9 kΩ 1% TPS2553 ILIM | G15: 0402 | H15: PASS | I15: 0.03 | J15: =B15*I15 -> 0.09 | L15: ≈ 1.0 A. Do not leave ILIM open.
A16: 12 | B16: 1 | C16: U31 | D16: TLV75533PDBVR | E16: Texas Instruments | F16: SYS_5V → 3.3 V LDO 500 mA, hand-solder | G16: SOT-23-5 | H16: POWER | I16: 0.36 | J16: =B16*I16 -> 0.36 | L16: Same TLV755P as WSON. Gull-wing SOT-23-5. EN to SYS_5V. Quiet rail for VDD33 + four VCC33. Load ≤ 0.20 A.
A17: 13 | B17: 1 | C17: C31i | D17: GRM188R70J106ME47D | E17: Murata | F17: 10 µF 6.3 V LDO VIN | G17: 0603 | H17: PASS | I17: 0.08 | J17: =B17*I17 -> 0.08
A18: 14 | B18: 1 | C18: C31o | D18: GRM188R70J226ME47D | E18: Murata | F18: 22 µF 6.3 V LDO VOUT | G18: 0603 | H18: PASS | I18: 0.12 | J18: =B18*I18 -> 0.12
A19: 15 | B19: 1 | C19: U32 | D19: TLV62569PDDCR | E19: Texas Instruments | F19: SYS_5V → 1.1 V buck 2 A 1.5 MHz, hand-solder | G19: SOT-23-6 | H19: POWER | I19: 0.62 | J19: =B19*I19 -> 0.62 | L19: Replaces TPS62822 VSON. PG pin gates GRSTz. Vin abs-max 5.5 V — PESD5V0 required. η ~85–90 % at 5→1.1 V / 0.7 A. Keep-out island opposite Type-C / Y1. Size Iout 0.70 A.
A20: 16 | B20: 1 | C20: L32 | D20: XFL4015-102MEB | E20: Coilcraft | F20: 1.0 µH shielded Isat ~5 A (TLV62569 @ 1.5 MHz) | G20: 4×4 mm | H20: POWER | I20: 1.15 | J20: =B20*I20 -> 1.15 | L20: Not 470 nH — that value was for 2.2 MHz TPS62822. Start winding on SW. SW copper pad-sized only.
A21: 17 | B21: 1 | C21: C32i | D21: GRM188R70J106ME47D | E21: Murata | F21: 10 µF 6.3 V buck VIN at VIN/PGND | G21: 0603 | H21: PASS | I21: 0.08 | J21: =B21*I21 -> 0.08 | L21: First part next to U32 VIN/GND. SOT-23 still wants Cin touching the pins.
A22: 18 | B22: 2 | C22: C32o | D22: GRM188R70J106ME47D | E22: Murata | F22: 10 µF 6.3 V buck VOUT | G22: 0603 | H22: PASS | I22: 0.08 | J22: =B22*I22 -> 0.16
A23: 19 | B23: 1 | C23: R32t | D23: RC0402FR-07124KL | E23: Yageo | F23: 124 kΩ 1% FB top → 1.096 V | G23: 0402 | H23: PASS | I23: 0.02 | J23: =B23*I23 -> 0.02 | L23: Vout=0.6×(1+R1/R2).
A24: 20 | B24: 1 | C24: R32b | D24: RC0402FR-07150KL | E24: Yageo | F24: 150 kΩ 1% FB bottom to AGND | G24: 0402 | H24: PASS | I24: 0.02 | J24: =B24*I24 -> 0.02 | L24: Place at U32, not at the hub.
A25: 21 | B25: 1 | C25: FB32 | D25: BLM18PG300SN1D | E25: Murata | F25: Ferrite 30 Ω@100 MHz DCR~40 mΩ on 1.1 V | G25: 0603 | H25: PASS | I25: 0.1 | J25: =B25*I25 -> 0.1 | L25: DCR < 50 mΩ. Do not use a high-DCR EMI bead.
A26: 22 | B26: 1 | C26: C32h | D26: GRM155R70J106ME15D | E26: Murata | F26: 10 µF after ferrite on hub VDD island | G26: 0402 | H26: PASS | I26: 0.03 | J26: =B26*I26 -> 0.03
A27: 23 | B27: 1 | C27: Rpg | D27: RC0402FR-07100KL | E27: Yageo | F27: 100 kΩ PG pull-up to 3.3 V | G27: 0402 | H27: PASS | I27: 0.02 | J27: =B27*I27 -> 0.02 | L27: PG pull-up to 3.3 V on TLV62569P pin. Do not float if you use PG→GRSTz.
A28: 24 | B28: 1 | C28: Cgrst | D28: GRM155R71C105KA12D | E28: Murata | F28: 1 µF GRSTz to GND | G28: 0402 | H28: PASS | I28: 0.04 | J28: =B28*I28 -> 0.04 | L28: Hold reset until 3.3 V and 1.1 V are up.
A29: 25 | B29: 1 | C29: Q1 | D29: CSD17313Q2 | E29: Texas Instruments | F29: N-FET reverse-block SYS_5V | G29: SON-6 | H29: POWER | I29: 0.45 | J29: =B29*I29 -> 0.45 | L29: Optional. Gate from UP0 VBUS detect.
A30: 26 | B30: 1 | C30: J1 | D30: 124019572112A | E30: Amphenol ICC | F30: INPUT Type-C 24p mid-mount 5 A | G30: Mid-mount | H30: CONN | I30: 2.27 | J30: =B30*I30 -> 2.27 | L30: UP0. Parallel all VBUS and all GND pins.
A31: 27 | B31: 1 | C31: J2 | D31: 124019572112A | E31: Amphenol ICC | F31: OUTPUT DS1 Type-C 24p mid-mount 5 A | G31: Mid-mount | H31: CONN | I31: 2.27 | J31: =B31*I31 -> 2.27
A32: 28 | B32: 1 | C32: J3 | D32: 124019572112A | E32: Amphenol ICC | F32: OUTPUT DS2 Type-C 24p mid-mount 5 A | G32: Mid-mount | H32: CONN | I32: 2.27 | J32: =B32*I32 -> 2.27
A33: 29 | B33: 1 | C33: J4 | D33: 124019572112A | E33: Amphenol ICC | F33: OUTPUT DS3 Type-C 24p mid-mount 5 A | G33: Mid-mount | H33: CONN | I33: 2.27 | J33: =B33*I33 -> 2.27
A34: 30 | B34: 8 | C34: Uesd_ss | D34: TPD2EUSB30DRTR | E34: Texas Instruments | F34: 2-ch low-C SS ESD (2 per Type-C) | G34: SOT-5 | H34: PROT | I34: 0.42 | J34: =B34*I34 -> 3.36 | L34: <1 mm from connector pads.
A35: 31 | B35: 4 | C35: Uesd_cc | D35: TPD4E05U06DQAR | E35: Texas Instruments | F35: 4-ch ESD D+/D−/CC1/CC2 | G35: USON-10 | H35: PROT | I35: 0.38 | J35: =B35*I35 -> 1.52
A36: 32 | B36: 4 | C36: Dtv | D36: PESD5V0S1UL | E36: Nexperia | F36: 5 V TVS on each Type-C VBUS + clamp for 5.5 V-max buck | G36: SOD-323 | H36: PROT | I36: 0.08 | J36: =B36*I36 -> 0.32 | L36: Required. TPS62822 abs-max is 5.5 V.
A37: 33 | B37: 16 | C37: Cac | D37: GCM155R71C104KA55D | E37: Murata | F37: 100 nF 16 V SS TX AC-cap | G37: 0402 | H37: PASS | I37: 0.04 | J37: =B37*I37 -> 0.64 | L37: 4 per port. Follow HD3SS3220 side-of-mux.
A38: 34 | B38: 4 | C38: R900k | D38: RC0402FR-07900KL | E38: Yageo | F38: 900 kΩ VBUS_DET | G38: 0402 | H38: PASS | I38: 0.02 | J38: =B38*I38 -> 0.08
A39: 35 | B39: 3 | C39: R200k | D39: RC0402FR-07200KL | E39: Yageo | F39: 200 kΩ pull-up on DS ID | G39: 0402 | H39: PASS | I39: 0.02 | J39: =B39*I39 -> 0.06
A40: 36 | B40: 4 | C40: Cblk5 | D40: GRM21BR61A226ME51L | E40: Murata | F40: 22 µF 10 V on each Type-C VBUS | G40: 0805 | H40: PASS | I40: 0.08 | J40: =B40*I40 -> 0.32
A41: 37 | B41: 1 | C41: Cbulk | D41: 16SVP180MX | E41: Panasonic | F41: 180 µF 16 V OS-CON SYS_5V | G41: 8 mm | H41: PASS | I41: 0.85 | J41: =B41*I41 -> 0.85 | L41: USB hub bulk ≥120 µF.
...

Sheet Buy_List
A1: Case C buy list — one row per MPN
A3: MPN | B3: Mfr | C3: Total qty | D3: Unit USD | E3: Ext USD | F3: Used on
A4: TUSB8041ARGCR | B4: Texas Instruments | C4: =SUMIF(BOM!D:D,A4,BOM!B:B) -> 1 | D4: =IFERROR(INDEX(BOM!I:I,MATCH(A4,BOM!D:D,0)),0) -> 5.4 | E4: =C4*D4 -> 5.4 | F4: U1
A5: ABM8-24.000MHZ-B2-T | B5: Abracon | C5: =SUMIF(BOM!D:D,A5,BOM!B:B) -> 1 | D5: =IFERROR(INDEX(BOM!I:I,MATCH(A5,BOM!D:D,0)),0) -> 0.55 | E5: =C5*D5 -> 0.55 | F5: Y1
A6: GRM1555C1H120JA01D | B6: Murata | C6: =SUMIF(BOM!D:D,A6,BOM!B:B) -> 2 | D6: =IFERROR(INDEX(BOM!I:I,MATCH(A6,BOM!D:D,0)),0) -> 0.03 | E6: =C6*D6 -> 0.06 | F6: C_y
A7: HD3SS3220RNHR | B7: Texas Instruments | C7: =SUMIF(BOM!D:D,A7,BOM!B:B) -> 4 | D7: =IFERROR(INDEX(BOM!I:I,MATCH(A7,BOM!D:D,0)),0) -> 1.85 | E7: =C7*D7 -> 7.4 | F7: U2, U3, U4, U5
A8: TPS2553DBVR | B8: Texas Instruments | C8: =SUMIF(BOM!D:D,A8,BOM!B:B) -> 3 | D8: =IFERROR(INDEX(BOM!I:I,MATCH(A8,BOM!D:D,0)),0) -> 0.85 | E8: =C8*D8 -> 2.55 | F8: U6, U7, U8
A9: RC0402FR-0724K9L | B9: Yageo | C9: =SUMIF(BOM!D:D,A9,BOM!B:B) -> 3 | D9: =IFERROR(INDEX(BOM!I:I,MATCH(A9,BOM!D:D,0)),0) -> 0.03 | E9: =C9*D9 -> 0.09 | F9: Rilim
A10: TLV75533PDBVR | B10: Texas Instruments | C10: =SUMIF(BOM!D:D,A10,BOM!B:B) -> 1 | D10: =IFERROR(INDEX(BOM!I:I,MATCH(A10,BOM!D:D,0)),0) -> 0.36 | E10: =C10*D10 -> 0.36 | F10: U31
A11: GRM188R70J106ME47D | B11: Murata | C11: =SUMIF(BOM!D:D,A11,BOM!B:B) -> 4 | D11: =IFERROR(INDEX(BOM!I:I,MATCH(A11,BOM!D:D,0)),0) -> 0.08 | E11: =C11*D11 -> 0.32 | F11: C31i, C32i, C32o
A12: GRM188R70J226ME47D | B12: Murata | C12: =SUMIF(BOM!D:D,A12,BOM!B:B) -> 1 | D12: =IFERROR(INDEX(BOM!I:I,MATCH(A12,BOM!D:D,0)),0) -> 0.12 | E12: =C12*D12 -> 0.12 | F12: C31o
A13: TLV62569PDDCR | B13: Texas Instruments | C13: =SUMIF(BOM!D:D,A13,BOM!B:B) -> 1 | D13: =IFERROR(INDEX(BOM!I:I,MATCH(A13,BOM!D:D,0)),0) -> 0.62 | E13: =C13*D13 -> 0.62 | F13: U32
A14: XFL4015-102MEB | B14: Coilcraft | C14: =SUMIF(BOM!D:D,A14,BOM!B:B) -> 1 | D14: =IFERROR(INDEX(BOM!I:I,MATCH(A14,BOM!D:D,0)),0) -> 1.15 | E14: =C14*D14 -> 1.15 | F14: L32
A15: RC0402FR-07124KL | B15: Yageo | C15: =SUMIF(BOM!D:D,A15,BOM!B:B) -> 1 | D15: =IFERROR(INDEX(BOM!I:I,MATCH(A15,BOM!D:D,0)),0) -> 0.02 | E15: =C15*D15 -> 0.02 | F15: R32t
... A33: R30-1000402 | B33: Harwin | C33: =SUMIF(BOM!D:D,A33,BOM!B:B) -> 4 | D33: =IFERROR(INDEX(BOM!I:I,MATCH(A33,BOM!D:D,0)),0) -> 0.4 | E33: =C33*D33 -> 1.6 | F33: MH
D34: BUY TOTAL | E34: =SUM(E4:E33) -> 56.21
A35: Must match BOM board total | E35: =E34-BOM!J46 -> 0

Sheet Spec
A1: Case C locked spec
A3: Item | B3: Value
A4: Ports | B4: J1 Type-C UFP input + J2 J3 J4 Type-C DFP output. No barrel. No MCU.
A5: Data | B5: USB 3.2 Gen1 5 Gbps via TUSB8041A + 4× HD3SS3220
A6: Power in | B6: Host J1 VBUS 5 V only (7.5–15 W typical)
A7: Power out each DS | B7: 5 V, TPS2553 ILIM ≈ 1.0 A. Three ports share leftover host watts.
A8: 3.3 V | B8: TLV75533PDBVR LDO SOT-23-5, load ≤ 0.20 A
A9: 1.1 V | B9: TLV62569PDDCR buck SOT-23-6, size 0.70 A (563 mA typ 3× SS U0)
A10: Heat converters | B10: ~0.45–0.50 W worst case (LDO 0.34 W + buck ~0.12 W)
A11: Layout | B11: L32 1 µH + U32 opposite Type-C edge. Not under SS pairs or Y1.
A12: Hand solder | B12: Both converters are SOT-23 gull-wing. Iron + flux. No hot-bar required.
A13: Was / now | B13: Was WSON TLV75533PDRVR + VSON TPS62822 + 470 nH. Now SOT-23 + 1 µH.
